<?xml version="1.0" ?>
<robot name="martin" xmlns:xacro="http://www.ros.org/wiki/xacro">

<xacro:include filename="$(find robot)/urdf/materials.xacro" />
<xacro:include filename="$(find robot)/urdf/martin.trans" />
<xacro:include filename="$(find robot)/urdf/martin.gazebo" />
<xacro:include filename="$(find robot)/urdf/plugins/gps.xacro" />
<xacro:include filename="$(find robot)/urdf/plugins/imu.xacro" />
<xacro:include filename="$(find robot)/urdf/plugins/laser_sensor.xacro" />
<xacro:include filename="$(find robot)/urdf/plugins/zed2.xacro" />

<xacro:property name="PI" value="3.14"/>

<link name="base_link">
  <inertial>
    <origin rpy="0 0 0" xyz="-0.010646286022740195 -4.919653835224294e-16 0.07524542881356616"/>
    <mass value="47.91821428809842"/>
    <inertia ixx="0.350848" ixy="0.0" ixz="0.027353" iyy="1.008832" iyz="-0.0" izz="1.186927"/>
  </inertial>
  <visual>
    <origin rpy="0 0 0" xyz="0 0 0"/>
    <geometry>
      <mesh filename="package://robot/meshes/base_link.stl" scale="0.001 0.001 0.001"/>
    </geometry>
    <material name="orange"/>
  </visual>
  <collision>
    <origin rpy="0 0 0" xyz="0 0 0"/>
    <geometry>
      <mesh filename="package://robot/meshes/base_link.stl" scale="0.001 0.001 0.001"/>
    </geometry>
  </collision>
</link>

<link name="wheel_front_left_1">
  <inertial>
    <origin rpy="0 0 0" xyz="2.3943220794908626e-08 -0.009939147977344326 -1.8492763799449197e-08"/>
    <mass value="0.552895033700559"/>
    <inertia ixx="0.001246" ixy="0.0" ixz="-0.0" iyy="0.002096" iyz="-0.0" izz="0.001246"/>
  </inertial>
  <visual>
    <origin rpy="0 0 0" xyz="-0.01 0.005 -0.017"/>
    <geometry>
      <mesh filename="package://robot/meshes/wheel.dae"/>
    </geometry>
    <material name="silver"/>
  </visual>
  <collision>
    <origin rpy="${PI/2} 0 0" xyz="0 0 0"/>
    <geometry>
      <cylinder length="0.07" radius="0.08"/>
    </geometry>
  </collision>
</link>

<link name="wheel_front_right_1">
  <inertial>
    <origin rpy="0 0 0" xyz="1.796076479210207e-08 0.009939147977344354 1.3632938049290555e-08"/>
    <mass value="0.5528950337005641"/>
    <inertia ixx="0.001246" ixy="-0.0" ixz="0.0" iyy="0.002096" iyz="-0.0" izz="0.001246"/>
  </inertial>
  <visual>
    <origin rpy="0 0 ${PI}" xyz="0.01 -0.005 -0.017"/>
    <geometry>
      <mesh filename="package://robot/meshes/wheel.dae"/>
    </geometry>
    <material name="silver"/>
  </visual>
  <collision>
    <origin rpy="${PI/2} 0 0" xyz="0 0 0"/>
    <geometry>
      <cylinder length="0.07" radius="0.08"/>
    </geometry>
  </collision>
</link>

<link name="wheel_rear_left_1">
  <inertial>
    <origin rpy="0 0 0" xyz="2.481888500271978e-08 -0.009939147977344326 -1.6256707337930498e-08"/>
    <mass value="0.552895033700561"/>
    <inertia ixx="0.001246" ixy="0.0" ixz="-0.0" iyy="0.002096" iyz="-0.0" izz="0.001246"/>
  </inertial>
  <visual>
    <origin rpy="0 0 0" xyz="-0.01 0.005 -0.017"/>
    <geometry>
      <mesh filename="package://robot/meshes/wheel.dae"/>
    </geometry>
    <material name="silver"/>
  </visual>
  <collision>
    <origin rpy="${PI/2} 0 0" xyz="0 0 0"/>
    <geometry>
      <cylinder length="0.07" radius="0.08"/>
    </geometry>
  </collision>
</link>

<link name="wheel_rear_right_1">
  <inertial>
    <origin rpy="0 0 0" xyz="2.1544820399954645e-08 0.00993914797734427 1.3912224119255745e-08"/>
    <mass value="0.5528950337005801"/>
    <inertia ixx="0.001246" ixy="-0.0" ixz="0.0" iyy="0.002096" iyz="-0.0" izz="0.001246"/>
  </inertial>
  <visual>
    <origin rpy="0 0 ${PI}" xyz="0.01 -0.005 -0.017"/>
    <geometry>
      <mesh filename="package://robot/meshes/wheel.dae"/>
    </geometry>
    <material name="silver"/>
  </visual>
  <collision>
    <origin rpy="${PI/2} 0 0" xyz="0 0 0"/>
    <geometry>
      <cylinder length="0.07" radius="0.08"/>
    </geometry>
  </collision>
</link>

<joint name="joint_front_left" type="continuous">
  <origin rpy="0 0 0" xyz="0.125 0.16 0.03"/>
  <parent link="base_link"/>
  <child link="wheel_front_left_1"/>
  <axis xyz="0.0 1.0 0.0"/>
  <limit effort="10000" velocity="1000"/>
  <joint_properties damping="1.0" friction="1.0"/>
</joint>

<joint name="joint_front_right" type="continuous">
  <origin rpy="0 0 0" xyz="0.125 -0.16 0.03"/>
  <parent link="base_link"/>
  <child link="wheel_front_right_1"/>
  <axis xyz="0.0 1.0 0.0"/>
  <limit effort="10000" velocity="1000"/>
  <joint_properties damping="1.0" friction="1.0"/>
</joint>

<joint name="joint_rear_left" type="continuous">
  <origin rpy="0 0 0" xyz="-0.125 0.16 0.03"/>
  <parent link="base_link"/>
  <child link="wheel_rear_left_1"/>
  <axis xyz="0.0 1.0 0.0"/>
  <limit effort="10000" velocity="1000"/>
  <joint_properties damping="1.0" friction="1.0"/>
</joint>

<joint name="joint_rear_right" type="continuous">
  <origin rpy="0 0 0" xyz="-0.125 -0.16 0.03"/>
  <parent link="base_link"/>
  <child link="wheel_rear_right_1"/>
  <axis xyz="0.0 1.0 0.0"/>
  <limit effort="10000" velocity="1000"/>
  <joint_properties damping="1.0" friction="1.0"/>
</joint>

<joint name="zed2_tilt_head_joint" type="fixed">
  <origin xyz="0.25 0 0.02" rpy="0 0.02 0"/>
  <parent link="base_link"/>
  <child link="zed2_tilt_head_link"/>
</joint>

<link name="zed2_tilt_head_link">
    <inertial>
      <mass value="0.108614"/>
      <origin xyz="0 -0.008564 0.015313"/>
      <inertia
        ixx="7.371e-5" ixy="0.0" ixz="1.326071e-6"
        iyy="3.14e-5" iyz="-1.424e-5"
        izz="6.13e-5"/>
    </inertial>
    <visual>
      <origin xyz="0 0 0" rpy="0 0 ${pi}"/>
      <geometry>
        <mesh filename="package://robot/meshes/zed2_base.dae"/>
      </geometry>
    </visual>
    <collision>
      <origin xyz="0 0 0" rpy="0 0 ${pi}"/>
      <geometry>
        <mesh filename="package://robot/meshes/zed2_base.dae"/>
      </geometry>
    </collision>
  </link>


<joint name="zed2_camera_center_joint" type="fixed">
  <parent link="zed2_tilt_head_link"/>
  <child link="zed2_camera_center"/>
  <origin xyz="0 0 0.0486" rpy="0 0.032637657 0"/>
</joint>

<xacro:zed2 link_prefix="" joint_prefix=""/>

<xacro:zed2_gazebo robot_ns="/"/> 

</robot>
